<?xml version="1.0" encoding="UTF-8"?>
<!-- Generated by org.testng.reporters.JUnitReportReporter -->
<testsuite skipped="5" hostname="USER-PC" name="TestngDependancy.TestngRetryFailDemo" tests="8" failures="1" timestamp="2020-09-02T22:47:56 IST" time="0.071" errors="0">
  <testcase name="Test3" time="0.010" classname="TestngDependancy.TestngRetryFailDemo">
    <skipped/>
  </testcase> <!-- Test3 -->
  <system-out/>
  <testcase name="Test3" time="0.000" classname="TestngDependancy.TestngRetryFailDemo">
    <skipped/>
  </testcase> <!-- Test3 -->
  <system-out/>
  <testcase name="Test3" time="0.011" classname="TestngDependancy.TestngRetryFailDemo">
    <skipped/>
  </testcase> <!-- Test3 -->
  <system-out/>
  <testcase name="Test3" time="0.010" classname="TestngDependancy.TestngRetryFailDemo">
    <failure type="java.lang.AssertionError">
      <![CDATA[java.lang.AssertionError
at org.junit.Assert.fail(Assert.java:87)
at org.junit.Assert.assertTrue(Assert.java:42)
at org.junit.Assert.assertTrue(Assert.java:53)
at TestngDependancy.TestngRetryFailDemo.Test3(TestngRetryFailDemo.java:27)
at sun.reflect.NativeMethodAccessorImpl.invoke0(Native Method)
at sun.reflect.NativeMethodAccessorImpl.invoke(Unknown Source)
at sun.reflect.DelegatingMethodAccessorImpl.invoke(Unknown Source)
at java.lang.reflect.Method.invoke(Unknown Source)
at org.testng.internal.MethodInvocationHelper.invokeMethod(MethodInvocationHelper.java:132)
at org.testng.internal.TestInvoker.invokeMethod(TestInvoker.java:599)
at org.testng.internal.TestInvoker.retryFailed(TestInvoker.java:214)
at org.testng.internal.MethodRunner.runInSequence(MethodRunner.java:58)
at org.testng.internal.TestInvoker$MethodInvocationAgent.invoke(TestInvoker.java:822)
at org.testng.internal.TestInvoker.invokeTestMethods(TestInvoker.java:147)
at org.testng.internal.TestMethodWorker.invokeTestMethods(TestMethodWorker.java:146)
at org.testng.internal.TestMethodWorker.run(TestMethodWorker.java:128)
at java.util.ArrayList.forEach(Unknown Source)
at org.testng.TestRunner.privateRun(TestRunner.java:764)
at org.testng.TestRunner.run(TestRunner.java:585)
at org.testng.SuiteRunner.runTest(SuiteRunner.java:384)
at org.testng.SuiteRunner.runSequentially(SuiteRunner.java:378)
at org.testng.SuiteRunner.privateRun(SuiteRunner.java:337)
at org.testng.SuiteRunner.run(SuiteRunner.java:286)
at org.testng.SuiteRunnerWorker.runSuite(SuiteRunnerWorker.java:53)
at org.testng.SuiteRunnerWorker.run(SuiteRunnerWorker.java:96)
at org.testng.TestNG.runSuitesSequentially(TestNG.java:1218)
at org.testng.TestNG.runSuitesLocally(TestNG.java:1140)
at org.testng.TestNG.runSuites(TestNG.java:1069)
at org.testng.TestNG.run(TestNG.java:1037)
at org.testng.remote.AbstractRemoteTestNG.run(AbstractRemoteTestNG.java:115)
at org.testng.remote.RemoteTestNG.initAndRun(RemoteTestNG.java:251)
at org.testng.remote.RemoteTestNG.main(RemoteTestNG.java:77)
]]>
    </failure>
  </testcase> <!-- Test3 -->
  <system-out/>
  <testcase name="Test2" time="0.010" classname="TestngDependancy.TestngRetryFailDemo"/>
  <system-out/>
  <testcase name="Test3" time="0.000" classname="TestngDependancy.TestngRetryFailDemo">
    <skipped/>
  </testcase> <!-- Test3 -->
  <system-out/>
  <testcase name="Test3" time="0.000" classname="TestngDependancy.TestngRetryFailDemo">
    <skipped/>
  </testcase> <!-- Test3 -->
  <system-out/>
  <testcase name="Test1" time="0.030" classname="TestngDependancy.TestngRetryFailDemo"/>
  <system-out/>
</testsuite> <!-- TestngDependancy.TestngRetryFailDemo -->
